Workbook

Sheet ReadMe
A1: Deployability toolkit
A3: Diagnostic, model, role, capital and risk decision support
A5: Colour key | B5: Yellow cells: you enter | C5: Blue cells: calculated, do not edit | D5: Grey panels: guidance and examples
A6: What this toolkit does | G6: How to score
A7: Use this toolkit to assess whether a social-impact or development opportunity is ready to move forward. It helps you build a clear, evidence-based view of: - how ready the opportunity is; - what is preventing it from moving forward; - which organisations should play which roles; - which partnership model is the best fit; - what types of capital may be needed, and in what order; and - how key risks should be allocated and managed. The toolkit turns these findings into a structured assessment that can support partnership design, internal decisions, stakeholder discussions and next-step planning. | G7: Use the 1 to 5 scale consistently: - 1: Critical weakness. The condition is absent or contradicted by the evidence. - 2: Significant gaps. Some elements exist, but they are informal, unreliable or untested. - 3: Partially developed. The condition works in a limited setting but is not yet robust or repeatable. - 4: Strong. The condition is operational, supported by evidence and broadly reliable. - 5: Fully ready. The condition is proven, repeatable and institutionally embedded. What "5" (optimal) means: not perfection. A 5 means a funder, partner or decision-maker would need no further evidence on this criterion to proceed, and the condition would survive a change of staff, budget cycle or leadership. Some tools use different scales (Severity and Immediacy, Likelihood and Impact, Need and Readiness, fit scores). Each tool shows its own key in row 5, a pop-up appears when you select a score cell, and the Scoring Guide tab describes what 1, 3 and 5 look like for every Scorecard criterion.
A17: How to use the toolkit | G17: Scoring rules
G18: - Score only what the available evidence supports. - A high score means the condition is demonstrably present, not simply planned or intended. - Record the evidence or rationale for each score. - If evidence is missing, leave the score blank or record the evidence gap. Do not guess. - Where participants disagree, record the different views and the reason for the disagreement. - Treat the score as a structured basis for discussion and decision-making, not as a substitute for judgement.
A19: Step 1: Complete the Opportunity Profile
A20: Record the basic information about the opportunity, including its location, sector, current stage, intended users or beneficiaries, potential payer, delivery actors and the decision the assessment needs to support. Output: A shared description of the opportunity and the scope of the assessment.
A30: Step 2: Complete the Deployability Scorecard
A31: Assess the opportunity across seven dimensions: demand, finance, operations, risk, institutions, legitimacy and enabling systems. For every score, record the evidence or reasoning behind it. Do not score an aspiration as if it were already in place. Output: An overall deployability score, a readiness rating and a view of the strongest and weakest dimensions.
A32: Step 3: Assess the Binding Constraints
A33: Identify the specific constraints preventing the opportunity from moving forward. Rate each for Severity and Immediacy; the tool multiplies them and ranks the constraints automatically. Treat the top-ranked constraint as a hypothesis: apply the binding-constraint test, then confirm or override it. Output: A ranked list of constraints, the confirmed primary binding constraint and an initial response.
A34: Step 4: Map the Relevant Actors
A35: Identify the organisations and stakeholder groups involved or required. Assess their mandates, incentives, authority, capacity, legitimacy and ability to carry risk. Output: A map of the current actors, the roles they could play and any important gaps in the partnership ecosystem
A36: Step 5: Assess System Readiness
A37: Examine whether the surrounding systems can support implementation and scale. This includes financial, administrative, regulatory, operational, data, community-engagement and accountability systems. Output: A view of the enabling systems that are ready, the systems that need strengthening and the actions required. | G37: Working-version notice
A38: Step 6: Select the Partnership Model | G38: This workbook is a working Version 1 designed for testing, feedback and revision. Its questions, scoring thresholds, model logic and weightings should be tested against real opportunities before they are treated as final. Thresholds and weightings are transparent and may be edited where marked. When changes are made, record: - what was changed; - why it was changed; - who approved the change; - the date of the change; and - the version number. This will help preserve consistency across assessments while allowing the toolkit to improve through use.
A39: Use the evidence from the earlier tools to assess which partnership model best addresses the opportunity’s main constraints: 1. Aggregation and Warehouse Platforms for fragmented or sub-scale opportunities; 2. Integrated Project Preparation and Guarantee Platforms for underprepared opportunities or risks that require structured mitigation; or 3. Predictable Delivery Networks for fragmented providers, inconsistent delivery systems or weak purchasing and payment arrangements. Some opportunities may require a hybrid model or a sequence of models. Output: A recommended primary partnership model, any supporting model and the conditions required for the model to work.
A40: Step 7: Select Institutional Roles
A41: Test which roles one institution (by default the lead institution) can credibly play, scoring mandate, authority, capability, resources, legitimacy and risk appetite for each role. Copy the tab to assess another institution. A role should follow capability, not ambition. Output: Candidate roles, roles to assign to other actors, and role boundaries.
A42: Step 8: Plan the Capital Pathway
A43: Identify which forms of capital are appropriate at the opportunity’s current stage and what may be required later. Consider grants, market-building grants, technical assistance, catalytic capital, first-loss capital, guarantees, concessional finance, blended finance, domestic capital, commercial capital and capital recycling. Capital should follow readiness and address a defined constraint. It should not be used to hide weak demand, poor preparation or an unclear operating model. Output: A proposed capital pathway showing the instruments, providers, conditions and sequence of support.
A44: Step 9: Allocate and Manage Risk
A45: Identify the material risks, assess their likelihood and impact, and determine which actor is best placed to manage each one. Record the proposed treatment, mitigation instrument, residual risk and monitoring trigger. Output: A risk-allocation plan showing who carries each risk, how it will be managed and what remains after mitigation. | G45: What the workbook calculates for you
A46: Step 10: Review the Dashboard | G46: Scorecard: dimension averages, RAG status, overall score (/140), overall rating and the weakest dimension. Binding Constraints: priority score (Severity x Immediacy), primary and secondary constraint, and a suggested model. Actor Map: overall fit per actor and the strongest actor. System Readiness: average and RAG per system, and the weakest system. Partnership Model Selection: average fit per model and the recommended model. Role Selection: overall fit per role, best-fit role and top three candidate roles. Capital Sequencing: highest-need and most-ready capital type. Risk Allocation: inherent score per risk, the highest risk and average residual risk. Dashboard: pulls all of the above onto one page. What stays with you: the evidence, the scores, the binding-constraint test, and every final decision. The calculations are prompts for discussion, not answers.
A47: Use the dashboard to bring the main findings together. Review the deployability score, binding constraint, recommended model, institutional role, capital priority and highest risks. Use these findings to agree on a decision, the next three actions, action owners, timing and any assumptions that still need to be tested. Output: A concise decision summary and action plan.
G60: Short on time? Rapid screen
G61: For a first screen, complete only the Opportunity Profile, Deployability Scorecard and Binding Constraints (with the relevant Word interview and political economy sections). Complete the remaining tools when the opportunity moves to full partnership design.

Sheet Scoring Guide
A1: Scoring Guide
A3: What each score looks like. Use this when you are unsure between two numbers. Score 2 and 4 sit between the descriptions shown. If none of the descriptions fits and there is no evidence, leave the score blank and record a priority action.
A5: Part A. What a 5 (optimal) means
A6: A 5 does not mean perfect. It means the condition is proven, repeatable and institutionally embedded: a funder, partner or decision-maker would need no further evidence on this criterion to proceed, and the condition would survive a change of staff, budget cycle or leadership. A 4 is operational and evidenced but not yet proven over time or at scale.
A8: Part B. Deployability Scorecard: criterion-by-criterion
A9: ID | B9: Criterion | C9: 1 looks like... | D9: 3 looks like... | E9: 5 looks like...
A10: D1 | B10: Demand visibility | C10: Users or purchasers are not identified, or need is assumed. | D10: Users identified and need evidenced in a limited area or by one source. | E10: Users and purchasers named and sized; need confirmed by several independent sources across the target area.
A11: D2 | B11: Bankable demand | C11: Need exists but no one pays or is mandated to pay. | D11: A payment route exists for part of the demand (e.g. pilot contract, partial reimbursement). | E11: Demand is linked to an operating payment mechanism (budget line, tariff, contract, offtake) at target scale.
A12: D3 | B12: Payer credibility | C12: No payer identified, or the payer lacks authority or budget. | D12: Payer has authority and a budget line or letter of intent, but a limited or irregular payment record. | E12: Multi-year budgeted, enforceable commitment and two or more years of on-time payment.
A13: D4 | B13: Demand predictability | C13: Volumes cannot be estimated. | D13: Volumes estimated from pilot or proxy data, with wide ranges. | E13: Volumes forecast from multi-year data or contractual commitments, with narrow ranges.
A14: F1 | B14: Revenue / repayment logic | C14: No identified source of revenue or repayment. | D14: Source identified but untested, or covers only part of costs. | E14: Source is contracted or proven and covers costs or repayment at target scale.
A15: F2 | B15: Cash-flow visibility | C15: No cash-flow model. | D15: Model built on assumptions; timing and variability partly evidenced. | E15: Model uses actual data; timing and variability evidenced and stress-tested.
A16: F3 | B16: Capital fit | C16: Instruments do not match stage or risk (e.g. commercial debt before revenue). | D16: Mostly matched, but some instruments are premature or untested with providers. | E16: Every instrument matches readiness, and a provider has confirmed interest on those terms.
A17: F4 | B17: Capital sequencing | C17: No view beyond current funding. | D17: Later sources named, but triggers or milestones unclear. | E17: Each next source named, with agreed milestones that trigger its entry.
A18: O1 | B18: Operating model | C18: Activities and responsibilities undefined. | D18: Defined on paper, or proven only in a pilot. | E18: Documented, operating, and responsibilities contractually assigned.
A19: O2 | B19: Provider capacity | C19: Providers lack capacity and there is no credible plan to build it. | D19: Capacity sufficient for a pilot; scale-up plan exists but is unfunded or untested. | E19: Providers already operate at or near target scale with acceptable quality.
A20: O3 | B20: Standards and verification | C20: No common standards or verification. | D20: Standards exist but are applied inconsistently, or verification is manual or partial. | E20: Standards applied across providers; verification is routine and trusted by payers.
... A37: S4 | B37: Regulatory and enabling environment | C37: Licensing or policy blocks the model. | D37: Workable with exemptions, delays or pending reform. | E37: Regulation, licensing and enforcement support the model.
A39: Part C. Scales used in the other tools
A40: Tool | B40: Scale | C40: 1 means... | D40: 3 means... | E40: 5 means...
A41: Tool 2 | B41: Severity | C41: Minor friction; a workaround exists. | D41: Materially weakens the case; must be addressed in the design. | E41: The opportunity cannot proceed until it is resolved.
A42: Tool 2 | B42: Immediacy | C42: Matters only at scale (24+ months). | D42: Must be resolved within the next stage (6-12 months). | E42: Blocks the very next decision or action (0-90 days).
A43: Tool 3 | B43: Actor criteria (mandate, incentive, authority, capacity, legitimacy, risk-bearing) | C43: Absent, or works against the opportunity. | D43: Partial or conditional. | E43: Demonstrated and documented for this kind of role.
A44: Tool 4 | B44: System readiness | C44: Absent or contradicted by evidence. | D44: Works in a limited setting; not yet repeatable. | E44: Proven, repeatable and institutionally embedded.
A45: Tool 5 | B45: How true is the statement? | C45: Not true or not applicable. | D45: Partly true, or true in some areas. | E45: Dominant feature, true across the opportunity.
A46: Tool 6 | B46: Role fit (six criteria) | C46: Poor fit. | D46: Possible with support. | E46: Strong, proven fit.
A47: Tool 7 | B47: Need | C47: Not needed at this stage. | D47: Useful, but does not address the binding constraint. | E47: Directly addresses the validated binding constraint now.
A48: Tool 7 | B48: Readiness | C48: Entry conditions not met. | D48: Some conditions met; provider interest unconfirmed. | E48: Conditions met and a provider is ready to commit.
A49: Tool 8 | B49: Likelihood (next 24 months) | C49: Rare (under 10%). | D49: Possible (30-50%). | E49: Almost certain (over 80%).
A50: Tool 8 | B50: Impact | C50: Negligible. | D50: Material delay or cost; a component must be redesigned. | E50: Stops the opportunity or causes serious harm to users.
A51: Tool 8 | B51: Residual risk (after mitigation) | C51: Low; accept and monitor. | D51: Material; needs active management. | E51: Could still stop the opportunity.
A52: Direction matters: on the Scorecard, System Readiness, Actor Map, Role Selection and Readiness, 5 is better. For Severity, Immediacy, Likelihood, Impact and Residual risk, 5 is worse.

Sheet Opportunity Profile
A1: Opportunity Profile
A3: Complete once. Key fields are pulled into the dashboard. Yellow cells are for you to fill in.
A6: Core information
A7: Opportunity name
A8: Country/geography
A9: Sector
A10: Lead institution
A11: Assessment date
A12: Assessment lead
A13: Current stage
A14: Short description
A15: Primary beneficiaries/users
... A21: Key decision this assessment should support

Sheet Deployability Scorecard
A1: Tool 1 | Deployability Scorecard
A3: Score each criterion 1 to 5 using evidence (key in row 5; criterion-by-criterion descriptions in the Scoring Guide tab). Blank means not yet scored or no evidence, and is treated as incomplete, not zero. Yellow cells are for you; blue cells calculate automatically.
A5: SCORING KEY 1 = Critical weakness: absent or contradicted by evidence | 2 = Significant gaps: elements exist but are informal, unreliable or untested | 3 = Partially developed: works in a limited setting but not yet robust or repeatable | 4 = Strong: operational, evidenced and broadly reliable | 5 = Fully ready (optimal): proven, repeatable and institutionally embedded, so a decision-maker would need no further evidence on this point. Leave blank if there is no evidence. Criterion-by-criterion descriptions: Scoring Guide tab. Priority action: required for every score of 1 or 2 and every blank (examples below the summary).
A6: Opportunity | C6: ='Opportunity Profile'!B7 -> 0 | D6: Assessment Date | E6: ='Opportunity Profile'!B11 -> 0
A7: ID | B7: Dimension | C7: Assessment criterion | D7: Score (1-5) | E7: Evidence / rationale | F7: Priority action (to raise the score or close the evidence gap) | G7: Action status
A8: D1 | B8: Demand and Market Readiness | C8: Demand visibility Target users, clients or purchasers are clearly identified and supported by evidence.
A9: D2 | B9: Demand and Market Readiness | C9: Bankable demand Need is linked to purchasing, reimbursement, procurement, offtake or recurring revenue.
A10: D3 | B10: Demand and Market Readiness | C10: Payer credibility The payer has willingness, authority, budget or liquidity, and a credible payment record.
A11: D4 | B11: Demand and Market Readiness | C11: Demand predictability Volumes, utilization or purchasing commitments can be forecast with reasonable confidence.
A12: F1 | B12: Financial and Capital Readiness | C12: Revenue/repayment logic Revenue, reimbursement, cost recovery or repayment sources are explicit.
A13: F2 | B13: Financial and Capital Readiness | C13: Cash-flow visibility Timing, amount and variability of inflows and outflows can be modelled.
A14: F3 | B14: Financial and Capital Readiness | C14: Capital fit The proposed instruments match the opportunity’s readiness, risk and affordability needs.
A15: F4 | B15: Financial and Capital Readiness | C15: Capital sequencing There is a credible path from current support to later-stage financing or durable public/grant funding.
A16: O1 | B16: Delivery and Operational Readiness | C16: Operating model Activities, delivery channels, responsibilities and operating requirements are defined.
A17: O2 | B17: Delivery and Operational Readiness | C17: Provider capacity Delivery actors have or can build the capacity to perform at the intended scale.
A18: O3 | B18: Delivery and Operational Readiness | C18: Standards and verification Quality, service, reporting and verification requirements are clear and usable.
A19: O4 | B19: Delivery and Operational Readiness | C19: Repeatability The model can be replicated through standard processes, contracts, data and role definitions.
... A35: S4 | B35: System Readiness | C35: Regulatory and enabling environment Licensing, policy, infrastructure and enforcement conditions are workable.
A37: Dimension summary
A38: Dimension | B38: Average / 5 | C38: Score / 20 | D38: Completion | E38: RAG | F38: Primary Interpretation
A39: Demand and Market Readiness | B39: =IFERROR(AVERAGE(D8:D11), 0) -> 0 | C39: =B39*4 -> 0 | D39: =COUNT(D8:D11)/4 -> 0 | E39: =IF(B39=0, "Incomplete", IF(B39<2.5, "Red", IF(B39<3.5, "Amber", "Green"))) -> Incomplete | F39: =IF(B39=0, "Complete the assessment", IF(B39<2.5, "Binding or critical weakness", IF(B39<3.5, "Requires targeted structuring", "Strong readiness condition"))) -> Complete the assessment
A40: Financial and Capital Readiness | B40: =IFERROR(AVERAGE(D12:D15), 0) -> 0 | C40: =B40*4 -> 0 | D40: =COUNT(D12:D15)/4 -> 0 | E40: =IF(B40=0, "Incomplete", IF(B40<2.5, "Red", IF(B40<3.5, "Amber", "Green"))) -> Incomplete | F40: =IF(B40=0, "Complete the assessment", IF(B40<2.5, "Binding or critical weakness", IF(B40<3.5, "Requires targeted structuring", "Strong readiness condition"))) -> Complete the assessment
A41: Delivery and Operational Readiness | B41: =IFERROR(AVERAGE(D16:D19), 0) -> 0 | C41: =B41*4 -> 0 | D41: =COUNT(D16:D19)/4 -> 0 | E41: =IF(B41=0, "Incomplete", IF(B41<2.5, "Red", IF(B41<3.5, "Amber", "Green"))) -> Incomplete | F41: =IF(B41=0, "Complete the assessment", IF(B41<2.5, "Binding or critical weakness", IF(B41<3.5, "Requires targeted structuring", "Strong readiness condition"))) -> Complete the assessment
A42: Risk and Structuring Readiness | B42: =IFERROR(AVERAGE(D20:D23), 0) -> 0 | C42: =B42*4 -> 0 | D42: =COUNT(D20:D23)/4 -> 0 | E42: =IF(B42=0, "Incomplete", IF(B42<2.5, "Red", IF(B42<3.5, "Amber", "Green"))) -> Incomplete | F42: =IF(B42=0, "Complete the assessment", IF(B42<2.5, "Binding or critical weakness", IF(B42<3.5, "Requires targeted structuring", "Strong readiness condition"))) -> Complete the assessment
A43: Institutional and Coordination Readiness | B43: =IFERROR(AVERAGE(D24:D27), 0) -> 0 | C43: =B43*4 -> 0 | D43: =COUNT(D24:D27)/4 -> 0 | E43: =IF(B43=0, "Incomplete", IF(B43<2.5, "Red", IF(B43<3.5, "Amber", "Green"))) -> Incomplete | F43: =IF(B43=0, "Complete the assessment", IF(B43<2.5, "Binding or critical weakness", IF(B43<3.5, "Requires targeted structuring", "Strong readiness condition"))) -> Complete the assessment
A44: Legitimacy and Community Readiness | B44: =IFERROR(AVERAGE(D28:D31), 0) -> 0 | C44: =B44*4 -> 0 | D44: =COUNT(D28:D31)/4 -> 0 | E44: =IF(B44=0, "Incomplete", IF(B44<2.5, "Red", IF(B44<3.5, "Amber", "Green"))) -> Incomplete | F44: =IF(B44=0, "Complete the assessment", IF(B44<2.5, "Binding or critical weakness", IF(B44<3.5, "Requires targeted structuring", "Strong readiness condition"))) -> Complete the assessment
A45: System Readiness | B45: =IFERROR(AVERAGE(D32:D35), 0) -> 0 | C45: =B45*4 -> 0 | D45: =COUNT(D32:D35)/4 -> 0 | E45: =IF(B45=0, "Incomplete", IF(B45<2.5, "Red", IF(B45<3.5, "Amber", "Green"))) -> Incomplete | F45: =IF(B45=0, "Complete the assessment", IF(B45<2.5, "Binding or critical weakness", IF(B45<3.5, "Requires targeted structuring", "Strong readiness condition"))) -> Complete the assessment
A47: Overall deployability score | B47: =SUM(C39:C45) -> 0 | C47: /140
A48: Overall rating | B48: =IF(B47=0, "Incomplete", IF(B47>=120, "Deployable", IF(B47>=100, "Near deployable", IF(B47>=80, "Requires structuring", IF(B47>=60, "Early stage", "Pre-deployability"))))) -> Incomplete
A49: Lowest-scoring dimension | B49: =IF(B47=0, "Incomplete", INDEX(A39:A45, MATCH(_xlfn.MINIFS(B39:B45, D39:D45, ">0"), B39:B45, 0))) -> Incomplete
A51: How to read the results
A52: Dimension RAG | B52: Red = average below 2.5: a binding or critical weakness. Amber = 2.5 to 3.4: needs targeted structuring. Green = 3.5 or above: a strong readiness condition. A partly scored dimension shows a provisional RAG; check the Completion column.
A53: Deployable (120-140) | B53: Ready for financing or implementation decisions; remaining weaknesses are minor and owned.
A54: Near deployable (100-119) | B54: One or two dimensions need targeted work. Proceed with explicit conditions.
A55: Requires structuring (80-99) | B55: Several material weaknesses. Design and preparation work is needed before financing.
A56: Early stage (60-79) | B56: Foundational gaps across several dimensions. Focus on evidence, preparation and ownership.
A57: Pre-deployability (below 60) | B57: Not yet ready to structure. Validate demand, payment and ownership first.
A59: Priority action: what to write (examples, not counted)
A60: A priority action is the single most important step that would raise a weak score or close an evidence gap. Write one for every criterion scored 1 or 2 or left blank. Say what will be done, by whom, by when, and what evidence will show it is done. Track it in the Action status column.
A61: D3 Payer credibility, scored 2 | B61: Obtain written confirmation of the FY27 budget line from the provincial health department and 12 months of payment records from the district treasury. Owner: Evidence lead. By: 30 Nov. Done when: both documents are filed and summarised in the Evidence column.
...

Sheet Binding Constraints
A1: Tool 2 | Binding Constraint Assessment
A3: Rate each constraint for Severity and Immediacy (key in row 5). The tool multiplies them (priority score, maximum 25) and ranks the constraints automatically: the highest becomes the primary binding constraint and drives the suggested model. Treat that as a starting hypothesis: apply the binding-constraint test, then confirm or override it in row 22. Note: here 5 means worse; on the Scorecard 5 means better.
A5: SEVERITY: how much does this block progress? 1 = Minor friction; a workaround exists | 2 = Adds cost or delay but does not change the design | 3 = Materially weakens the case; must be addressed in the design | 4 = Progress possible only at small scale or with a major workaround | 5 = The opportunity cannot proceed until it is resolved. IMMEDIACY: how soon must it be resolved? 1 = Matters only at scale (24+ months) | 2 = Within 12 to 24 months | 3 = Within the next stage (6 to 12 months) | 4 = Within 3 to 6 months | 5 = Blocks the very next decision or action (0 to 90 days).
A6: ID | B6: Constraint | C6: Diagnostic test | D6: Severity (1 = minor, 5 = blocks progress) | E6: Immediacy (1 = later, 5 = now) | F6: Priority score (S x I) | G6: Evidence / root cause | H6: Suggested response
A7: C1 | B7: Demand visibility | C7: Is use or need visible, validated and specific enough to support design? | F7: =IF(COUNT(D7:E7)<2, "", D7*E7) | H7: Validate demand and adoption.
A8: C2 | B8: Payment credibility | C8: Is there a reliable payer, budget, reimbursement, purchase or offtake mechanism? | F8: =IF(COUNT(D8:E8)<2, "", D8*E8) | H8: Strengthen purchaser/payment architecture.
A9: C3 | B9: Project preparation | C9: Are feasibility, commercial, legal, ESG, procurement and implementation requirements sufficiently prepared? | F9: =IF(COUNT(D9:E9)<2, "", D9*E9) | H9: Fund and coordinate preparation.
A10: C4 | B10: Risk allocation | C10: Are material risks explicit and held by actors able to manage them? | F10: =IF(COUNT(D10:E10)<2, "", D10*E10) | H10: Reallocate and mitigate specific risks.
A11: C5 | B11: Coordination ownership | C11: Is one credible actor responsible for moving the opportunity from concept to execution? | F11: =IF(COUNT(D11:E11)<2, "", D11*E11) | H11: Assign an ecosystem orchestrator.
A12: C6 | B12: Legitimacy and adoption | C12: Are trust, affordability, inclusion and accountability built into the model? | F12: =IF(COUNT(D12:E12)<2, "", D12*E12) | H12: Integrate CSOs, users and accountability systems.
A13: C7 | B13: Delivery capacity | C13: Can providers deliver at required quality, volume and continuity? | F13: =IF(COUNT(D13:E13)<2, "", D13*E13) | H13: Build or integrate delivery capacity.
A14: C8 | B14: Enabling systems | C14: Can procurement, regulation, payment, data and verification systems support scale? | F14: =IF(COUNT(D14:E14)<2, "", D14*E14) | H14: Strengthen foundations before scale.
A15: C9 | B15: Institutional commitment | C15: Are mandates, budgets, decision rights and commitments credible and durable? | F15: =IF(COUNT(D15:E15)<2, "", D15*E15) | H15: Secure formal commitments and authority.
A16: C10 | B16: Fragmentation / scale | C16: Are actors, assets, contracts or cash flows too dispersed or sub-scale? | F16: =IF(COUNT(D16:E16)<2, "", D16*E16) | H16: Consider aggregation and standardization.
A18: Prioritization output
A19: Primary binding constraint | B19: =IF(COUNT(F7:F16)=0, "Incomplete", INDEX(B7:B16, MATCH(MAX(F7:F16), F7:F16, 0))) -> Incomplete
A20: Secondary constraint | B20: =IF(COUNT(F7:F16)<2, "Incomplete", INDEX(B7:B16, MATCH(LARGE(F7:F16, 2), F7:F16, 0))) -> Incomplete
A21: Suggested primary model | B21: =IF(IF($B$22<>"",$B$22,$B$19)="Fragmentation / scale", "Model 1: Aggregation and Warehouse Platforms", IF(OR(IF($B$22<>"",$B$22,$B$19)="Project preparation", IF($B$22<>"",$B$22,$B$19)="Risk allocation", IF($B$22<>"",$B$22,$B$19)="Payment credibility"), "Model 2: Integrated Project Preparation + Guarantee Platforms", IF(OR(IF($B$22<>"",$B$22,$B$19)="Delivery capacity", IF($B$22<>"",$B$22,$B$19)="Legitimacy and adoption"), "Model 3: Predictable Delivery Networks", "Strengthen foundations before model selection"))) -> Strengthen foundations before model selection
A22: Confirmed binding constraint (after the test)
A23: Reason, if different from the ranked result
A25: Worked example (illustration only, not counted)
A26: C2 | B26: Payment credibility | D26: 5 | E26: 5 | F26: 25 | G26: No FY27 budget line; pilot payments averaged 120 days late. Root cause: purchasing sits outside the medium-term budget. | H26: Strengthen purchaser/payment architecture.
A27: C7 | B27: Delivery capacity | D27: 3 | E27: 2 | F27: 6 | G27: Clinics can absorb pilot volumes; capacity limits appear only beyond 60 sites. | H27: Build or integrate delivery capacity.
A28: Reading the example: payment credibility ranks first (25) and passes the test, because without a credible payer no clinic, lender or guarantor will commit. Delivery capacity is real but secondary: fixing it first would not unlock financing.

Sheet Actor Map
A1: Tool 3 | Actor Mapping
A3: List each organisation or group that is involved or needed (one per row) and score it 1 to 5 on the six criteria defined in row 5. Evidence comes from Word Tool 1 (Political Economy Assessment) and Tool 2 (Stakeholder Interview Guide). Overall fit is the simple average of the six scores. A worked example sits below the summary.
A5: WHAT EACH CRITERION ASKS Mandate: is the role within its formal remit? | Incentive: does it gain from success, or lose? (Word Tool 1, section 5) | Authority: can it commit decisions, budget or assets? (Tool 1, section 3) | Capacity: staff, systems, finance and track record to perform | Legitimacy: trusted by users, communities and peers? (Tool 1, section 8) | Risk-bearing: can it absorb losses or delays if things go wrong? SCALE 1 = Absent, or works against the opportunity | 2 = Weak or unproven | 3 = Partial or conditional | 4 = Clear and evidenced | 5 = Demonstrated and documented for this kind of role.
A6: Actor / institution | B6: Actor type | C6: Current / proposed role | D6: Mandate | E6: Incentive | F6: Authority | G6: Capacity | H6: Legitimacy | I6: Risk-bearing | J6: Overall fit | K6: Key contribution / evidence | L6: Gap or required action
J7: =IF(COUNT(D7:I7)=0, "", AVERAGE(D7:I7))
J8: =IF(COUNT(D8:I8)=0, "", AVERAGE(D8:I8))
J9: =IF(COUNT(D9:I9)=0, "", AVERAGE(D9:I9))
J10: =IF(COUNT(D10:I10)=0, "", AVERAGE(D10:I10))
J11: =IF(COUNT(D11:I11)=0, "", AVERAGE(D11:I11))
J12: =IF(COUNT(D12:I12)=0, "", AVERAGE(D12:I12))
J13: =IF(COUNT(D13:I13)=0, "", AVERAGE(D13:I13))
J14: =IF(COUNT(D14:I14)=0, "", AVERAGE(D14:I14))
J15: =IF(COUNT(D15:I15)=0, "", AVERAGE(D15:I15))
J16: =IF(COUNT(D16:I16)=0, "", AVERAGE(D16:I16))
J17: =IF(COUNT(D17:I17)=0, "", AVERAGE(D17:I17))
J18: =IF(COUNT(D18:I18)=0, "", AVERAGE(D18:I18))
... J26: =IF(COUNT(D26:I26)=0, "", AVERAGE(D26:I26))
A28: Actor system summary
A29: Strongest overall-fit actor | B29: =IF(COUNT(J7:J26)=0, "Incomplete", INDEX(A7:A26, MATCH(MAX(J7:J26), J7:J26, 0))) -> Incomplete
A30: Coordination owner identified?
A31: Credible payer/purchaser identified?
A32: Trusted community-facing actor identified?
A33: Critical missing actor/function
A35: Worked example (illustration only, not counted)
A36: Provincial Department of Health | B36: Government / public purchaser | C36: Purchaser | D36: 5 | E36: 4 | F36: 4 | G36: 2 | H36: 4 | I36: 2 | J36: 3.5 | K36: Budget holder for primary care; Tool 1 section 3 shows procurement sits with provincial treasury. | L36: Weak claims processing: pair with a network manager.
A37: Clinic owners association | B37: CSO / community-facing organisation | C37: Provider voice; accountability partner | D37: 3 | E37: 5 | F37: 2 | G37: 3 | H37: 5 | I37: 1 | J37: 3.2 | K37: Represents 140 clinics; highly trusted by members (8 interviews). | L37: Cannot carry financial risk: keep out of de-risking roles.

Sheet System Readiness
A1: Tool 4 | System Readiness Diagnostic
A3: Score how well each system works today, not what policy intends (same 1 to 5 scale as the Scorecard; key in row 5). This is the detailed view behind Scorecard criteria S1 to S4. Record the evidence, the action that would strengthen the system, and who owns it. Worked examples sit below the summary.
A5: SCORING KEY 1 = Critical weakness: absent or contradicted by evidence | 2 = Significant gaps: elements exist but are informal, unreliable or untested | 3 = Partially developed: works in a limited setting but not yet robust or repeatable | 4 = Strong: operational, evidenced and broadly reliable | 5 = Fully ready (optimal): proven, repeatable and institutionally embedded, so a decision-maker would need no further evidence on this point. Leave blank if there is no evidence. Criterion-by-criterion descriptions: Scoring Guide tab.
A6: ID | B6: System | C6: Readiness criterion | D6: Score (1–5) | E6: Evidence | F6: Strengthening action | G6: Owner
A7: SR1 | B7: Financial and administrative | C7: Payment rails are reliable, enforceable and timely.
A8: SR2 | B8: Financial and administrative | C8: Procurement is transparent, workable and sufficiently capable.
A9: SR3 | B9: Financial and administrative | C9: Public or institutional financial commitments are budget-backed and manageable.
A10: SR4 | B10: Regulatory and governance | C10: Licensing, approvals and compliance pathways are clear.
A11: SR5 | B11: Regulatory and governance | C11: Decision rights and coordination authority are credible.
A12: SR6 | B12: Regulatory and governance | C12: Contracts and accountability obligations can be enforced.
A13: SR7 | B13: Operational and delivery | C13: Logistics, infrastructure and service facilities support intended delivery.
A14: SR8 | B14: Operational and delivery | C14: Skilled personnel and institutional memory are sufficient.
A15: SR9 | B15: Operational and delivery | C15: Provider networks can maintain quality and continuity at scale.
A16: SR10 | B16: Data, verification and learning | C16: Performance data are usable, timely and sufficiently reliable.
A17: SR11 | B17: Data, verification and learning | C17: Verification supports claims, payments, outcomes or accountability.
A18: SR12 | B18: Data, verification and learning | C18: Learning loops can change implementation based on evidence.
... A27: SR21 | B27: Accountability, protection and monitoring | C27: Social performance is monitored alongside financial and delivery performance.
A29: System summary
A30: System | B30: Average / 5 | C30: Completion | D30: RAG
A31: Financial and administrative | B31: =IFERROR(AVERAGE(D7:D9),0) -> 0 | C31: =COUNT(D7:D9)/3 -> 0 | D31: =IF(B31=0, "Incomplete", IF(B31<2.5, "Red", IF(B31<3.5, "Amber", "Green"))) -> Incomplete
A32: Regulatory and governance | B32: =IFERROR(AVERAGE(D10:D12),0) -> 0 | C32: =COUNT(D10:D12)/3 -> 0 | D32: =IF(B32=0, "Incomplete", IF(B32<2.5, "Red", IF(B32<3.5, "Amber", "Green"))) -> Incomplete
A33: Operational and delivery | B33: =IFERROR(AVERAGE(D13:D15),0) -> 0 | C33: =COUNT(D13:D15)/3 -> 0 | D33: =IF(B33=0, "Incomplete", IF(B33<2.5, "Red", IF(B33<3.5, "Amber", "Green"))) -> Incomplete
A34: Data, verification and learning | B34: =IFERROR(AVERAGE(D16:D18),0) -> 0 | C34: =COUNT(D16:D18)/3 -> 0 | D34: =IF(B34=0, "Incomplete", IF(B34<2.5, "Red", IF(B34<3.5, "Amber", "Green"))) -> Incomplete
A35: Relational and trust-based | B35: =IFERROR(AVERAGE(D19:D21),0) -> 0 | C35: =COUNT(D19:D21)/3 -> 0 | D35: =IF(B35=0, "Incomplete", IF(B35<2.5, "Red", IF(B35<3.5, "Amber", "Green"))) -> Incomplete
A36: Community engagement and participation | B36: =IFERROR(AVERAGE(D22:D24),0) -> 0 | C36: =COUNT(D22:D24)/3 -> 0 | D36: =IF(B36=0, "Incomplete", IF(B36<2.5, "Red", IF(B36<3.5, "Amber", "Green"))) -> Incomplete
A37: Accountability, protection and monitoring | B37: =IFERROR(AVERAGE(D25:D27),0) -> 0 | C37: =COUNT(D25:D27)/3 -> 0 | D37: =IF(B37=0, "Incomplete", IF(B37<2.5, "Red", IF(B37<3.5, "Amber", "Green"))) -> Incomplete
A39: Lowest-readiness system | B39: =IF(COUNT(D7:D27)=0, "Incomplete", INDEX(A31:A37, MATCH(_xlfn.MINIFS(B31:B37, C31:C37, ">0"), B31:B37, 0))) -> Incomplete
A42: Worked examples (illustration only, not counted)
A43: SR2 | B43: Financial and administrative | C43: Procurement is transparent, workable and sufficiently capable. | D43: 2 | E43: Comparable service tenders took 14-18 months in 2024-25 (provincial tender register); no framework agreement exists. | F43: Technical assistance to draft standard bid documents; explore a framework contract. | G43: Toolkit lead with treasury procurement unit
A44: SR11 | B44: Data, verification and learning | C44: Verification supports claims, payments, outcomes or accountability. | D44: 3 | E44: Pilot clinics submit paper claims; the district checks a 10% sample, about 6 weeks after the visit. | F44: Pilot digital claims capture in 20 clinics with automated checks before scale-up. | G44: Network manager (to be appointed)
A45: SR16 | B45: Community engagement and participation | C45: Users and communities can shape design and implementation. | D45: 4 | E45: Clinic committees meet quarterly and changed opening hours in 2025 (minutes reviewed); no youth representation. | F45: Add youth and disability representatives to two committees and track their input. | G45: CSO partner

Sheet Partnership Model Selection
A1: Tool 5 | Partnership Model Selection
A3: Score each diagnostic statement once: how true is it of this opportunity? (key in row 5). Each statement points to one model (column E). The tool averages the scores for each model and recommends the highest. Read the result alongside the confirmed binding constraint; if two models score closely, note a hybrid or sequence in row 24.
A5: SCALE: how true is this statement of the opportunity? 1 = Not true or not applicable | 2 = Slightly true | 3 = Partly true, or true in some areas | 4 = Largely true | 5 = Dominant feature, true across the opportunity. Statements M1 to M3 point to Model 1, M4 to M6 to Model 2, and M7 to M10 to Model 3.
A6: ID | B6: Selection criterion | C6: Diagnostic statement | D6: Score (1-5) | E6: Points to | G6: Evidence / rationale
A7: M1 | B7: Fragmentation | C7: Many similar actors, assets, contracts, receivables or cash flows are individually sub-scale. | E7: Model 1
A8: M2 | B8: Standardization potential | C8: Underlying opportunities are sufficiently similar for common eligibility, contracts and reporting. | E8: Model 1
A9: M3 | B9: Portfolio finance potential | C9: Pooled cash flows or assets could support warehouse, portfolio or take-out finance. | E9: Model 1
A10: M4 | B10: Preparation gap | C10: The opportunity is visible but feasibility, legal, financial, ESG or procurement preparation is incomplete. | E10: Model 2
A11: M5 | B11: Risk / payment security gap | C11: Specific payment, political, counterparty, completion or liquidity risks block participation. | E11: Model 2
A12: M6 | B12: Large or complex project | C12: Execution depends on approvals, procurement, contingent liabilities or major infrastructure structuring. | E12: Model 2
A13: M7 | B13: Existing providers | C13: Service providers already exist but operate in fragmented or weakly coordinated systems. | E13: Model 3
A14: M8 | B14: Standards and verification gap | C14: Provider accreditation, common standards, claims, invoices or verification are weak. | E14: Model 3
A15: M9 | B15: Working-capital need | C15: Providers face gaps between service delivery and payment that constrain continuity or scale. | E15: Model 3
A16: M10 | B16: Predictable purchasing potential | C16: A purchaser, insurer, buyer or sponsor could aggregate demand and pay against verified delivery. | E16: Model 3
A18: Model recommendation
A19: Model 1: Aggregation and Warehouse Platforms | B19: =IFERROR(AVERAGEIF($E$7:$E$16, "Model 1", $D$7:$D$16), 0) -> 0 | C19: Average fit / 5 (M1-M3)
A20: Model 2: Integrated Project Preparation + Guarantee Platforms | B20: =IFERROR(AVERAGEIF($E$7:$E$16, "Model 2", $D$7:$D$16), 0) -> 0 | C20: Average fit / 5 (M4-M6)
A21: Model 3: Predictable Delivery Networks | B21: =IFERROR(AVERAGEIF($E$7:$E$16, "Model 3", $D$7:$D$16), 0) -> 0 | C21: Average fit / 5 (M7-M10)
A23: Recommended primary model | B23: =IF(COUNT(D7:D16)=0, "Incomplete", INDEX(A19:A21, MATCH(MAX(B19:B21), B19:B21, 0))) -> Incomplete
A24: Sequencing / hybrid note

Sheet Role Selection
A1: Tool 6 | Institutional Role Selection Matrix
A3: This tab tests which roles ONE institution can credibly play, not which roles it would like to play. Score the institution named in row 4 against each role on six criteria (key in row 5), then record a decision for each role in column K. To assess another institution, copy this tab (right-click the tab > Move or Copy > Create a copy) and change row 4. The Actor Map scores all actors more broadly; this tab goes deeper on one.
A4: Institution being assessed | B4: =IF('Opportunity Profile'!B10="","Enter institution name",'Opportunity Profile'!B10) -> Enter institution name | E4: Defaults to the lead institution in the Opportunity Profile. Overwrite it to assess another institution.
A5: WHAT EACH CRITERION ASKS Mandate fit: is this role within its charter or strategy? | Authority: can it make the decisions this role requires? | Capability: does it have the skills, systems and track record? | Capital / resources: can it fund or staff the role? | Legitimacy: will partners and communities accept it in this role? | Risk appetite: will it accept the losses, liabilities or reputational exposure the role brings? SCALE 1 = Poor fit | 2 = Weak | 3 = Possible with support | 4 = Good fit | 5 = Strong, proven fit. Overall fit of 4 or more = candidate role; 2 or below = assign to another actor.
A6: Role | B6: Role description | C6: Mandate fit | D6: Authority | E6: Capability | F6: Capital / resources | G6: Legitimacy | H6: Risk appetite | I6: Overall fit | J6: Evidence / decision | K6: Role decision
A7: Funder | B7: Provides grants, preparation, concessional, catalytic or early-stage support. | I7: =IF(COUNT(C7:H7)=0, "", AVERAGE(C7:H7)) | L7: =IF(I7="", "", I7 + (100 - ROW()) / 100000)
A8: Convener | B8: Aligns actors around a shared pathway and decision process. | I8: =IF(COUNT(C8:H8)=0, "", AVERAGE(C8:H8)) | L8: =IF(I8="", "", I8 + (100 - ROW()) / 100000)
A9: Ecosystem orchestrator | B9: Maintains momentum from alignment to execution and reduces transaction friction. | I9: =IF(COUNT(C9:H9)=0, "", AVERAGE(C9:H9)) | L9: =IF(I9="", "", I9 + (100 - ROW()) / 100000)
A10: De-risker | B10: Covers specific risks through guarantees, first-loss, reserves or other instruments. | I10: =IF(COUNT(C10:H10)=0, "", AVERAGE(C10:H10)) | L10: =IF(I10="", "", I10 + (100 - ROW()) / 100000)
A11: Aggregator | B11: Pools actors, assets, contracts, receivables or cash flows. | I11: =IF(COUNT(C11:H11)=0, "", AVERAGE(C11:H11)) | L11: =IF(I11="", "", I11 + (100 - ROW()) / 100000)
A12: Purchaser | B12: Anchors demand through procurement, reimbursement, service contracts or offtake. | I12: =IF(COUNT(C12:H12)=0, "", AVERAGE(C12:H12)) | L12: =IF(I12="", "", I12 + (100 - ROW()) / 100000)
A13: Operator | B13: Manages delivery, infrastructure, services or implementation systems. | I13: =IF(COUNT(C13:H13)=0, "", AVERAGE(C13:H13)) | L13: =IF(I13="", "", I13 + (100 - ROW()) / 100000)
A14: Ecosystem builder | B14: Strengthens standards, capacity, data, regulation or enabling infrastructure. | I14: =IF(COUNT(C14:H14)=0, "", AVERAGE(C14:H14)) | L14: =IF(I14="", "", I14 + (100 - ROW()) / 100000)
A15: Market intelligence provider | B15: Generates evidence on demand, users, costs, behavior and adoption. | I15: =IF(COUNT(C15:H15)=0, "", AVERAGE(C15:H15)) | L15: =IF(I15="", "", I15 + (100 - ROW()) / 100000)
A16: Accountability partner | B16: Tracks inclusion, quality, grievances, trust and social performance. | I16: =IF(COUNT(C16:H16)=0, "", AVERAGE(C16:H16)) | L16: =IF(I16="", "", I16 + (100 - ROW()) / 100000)
A17: Strategy integrator | B17: Connects institutional ambition, resources and roles to execution. | I17: =IF(COUNT(C17:H17)=0, "", AVERAGE(C17:H17)) | L17: =IF(I17="", "", I17 + (100 - ROW()) / 100000)
A18: Champion | B18: Maintains senior sponsorship and resolves bottlenecks. | I18: =IF(COUNT(C18:H18)=0, "", AVERAGE(C18:H18)) | L18: =IF(I18="", "", I18 + (100 - ROW()) / 100000)
... A20: Local ownership steward | B20: Protects local leadership, capability, value capture and long-term ownership. | I20: =IF(COUNT(C20:H20)=0, "", AVERAGE(C20:H20)) | L20: =IF(I20="", "", I20 + (100 - ROW()) / 100000)
A22: Role recommendation
A23: Best-fit role | B23: =IF(COUNT(I7:I20)=0,"Incomplete",INDEX(A7:A20,MATCH(MAX(I7:I20),I7:I20,0))) -> Incomplete
A24: Role boundary / transition
A25: Top three candidate roles | B25: =IF(COUNT($L$7:$L$20)=0, "Incomplete", INDEX($A$7:$A$20, MATCH(LARGE($L$7:$L$20, 1), $L$7:$L$20, 0)) & IF(COUNT($L$7:$L$20)>=2, "; " & INDEX($A$7:$A$20, MATCH(LARGE($L$7:$L$20, 2), $L$7:$L$20, 0)), "") & IF(COUNT($L$7:$L$20)>=3, "; " & INDEX($A$7:$A$20, MATCH(LARGE($L$7:$L$20, 3), $L$7:$L$20, 0)), "")) -> Incomplete
A26: Roles to assign to another actor | B26: =COUNTIF($K$7:$K$20, "Assign to another actor") & " role(s): see column K and record owners on the Actor Map" -> 0 role(s): see column K and record owners on the Actor Map
A28: Worked example (illustration only, not counted). Institution assessed: a regional development finance institution
A29: De-risker | B29: Covers specific risks through guarantees, first-loss, reserves or other instruments. | C29: 5 | D29: 4 | E29: 4 | F29: 5 | G29: 3 | H29: 4 | I29: 4.2 | J29: Existing guarantee facility; board appetite for health exposure confirmed in interview. | K29: Lead institution takes role
A30: Operator | B30: Manages delivery, infrastructure, services or implementation systems. | C30: 1 | D30: 1 | E30: 2 | F30: 2 | G30: 3 | H30: 1 | I30: 1.7 | J30: No delivery mandate; would conflict with its investor role. | K30: Assign to another actor

Sheet Capital Sequencing
A1: Tool 7 | Impact Capital Continuum and Sequencing
A3: For each capital type, score Need and Readiness (key in row 5), then record the entry conditions, likely provider and stage. Capital follows readiness: a type with high Need but low Readiness belongs later in the sequence, once its conditions are met. Not every opportunity needs every type. A worked example sits below the output.
A5: NEED: does this opportunity need this capital now? 1 = Not needed at this stage | 2 = Marginal | 3 = Useful, but does not address the binding constraint | 4 = Important for a main constraint | 5 = Directly addresses the validated binding constraint now. READINESS: are the conditions to deploy it met? 1 = Entry conditions not met (see "Should not substitute for") | 2 = Few conditions met | 3 = Some conditions met; provider interest unconfirmed | 4 = Most conditions met; provider engaged | 5 = Conditions met and a provider is ready to commit.
A6: Capital type | B6: Appropriate use | C6: Should not substitute for | D6: Need (1-5) | E6: Readiness (1-5) | F6: Entry conditions / evidence | G6: Proposed provider / instrument | H6: Stage in sequence
A7: Grant capital | B7: Public-good functions, inclusion, trust, early pilots and demand validation. | C7: A sustainable operating or ownership model where one is required.
A8: Market-building grants | B8: Standards, coordination, provider readiness, market intelligence and pipeline development. | C8: Sustainable purchasing, financing or ownership arrangements.
A9: Technical assistance | B9: Feasibility, legal structuring, financial modelling, ESG, procurement and operational improvement. | C9: Absent demand, weak commitment or unresolved political barriers.
A10: Catalytic capital | B10: Absorb early uncertainty and crowd in additional participation. | C10: Weak economics, unclear revenue or poor preparation.
A11: First-loss capital | B11: Protect senior capital in portfolios and aggregation facilities. | C11: Fundamentally weak assets, contracts or cash flows.
A12: Guarantees | B12: Cover defined payment, political, completion, counterparty, liquidity or regulatory risks. | C12: Poor design, absent demand or incomplete preparation.
A13: Concessional finance | B13: Support a credible repayment pathway facing affordability, risk or market-readiness constraints. | C13: Permanent replacement for sustainable financing.
A14: Blended finance | B14: Combine public, philanthropic, concessional and commercial resources for a defined market failure. | C14: An opportunity with no credible sustainability pathway.
A15: Domestic capital | B15: Mobilize banks, pension funds, insurers, public funds, corporates or local investors. | C15: Poorly understood risks without preparation or safeguards.
A16: Commercial capital | B16: Finance credible revenue, repayment, enforceable contracts, manageable risk and sufficient scale. | C16: Unresolved structural risk or uncertain payment.
A17: Capital recycling | B17: Repay, refinance or redeploy capital through revolving or take-out pathways. | C17: Unproven repayment or assumed refinancing.
A19: Capital pathway output
A20: Highest-need capital type | B20: =IF(COUNT(D7:D17)=0,"Incomplete",INDEX(A7:A17,MATCH(MAX(D7:D17),D7:D17,0))) -> Incomplete
A21: Most ready capital type | B21: =IF(COUNT(E7:E17)=0,"Incomplete",INDEX(A7:A17,MATCH(MAX(E7:E17),E7:E17,0))) -> Incomplete
A22: Proposed capital stack summary
A25: Worked example (illustration only, not counted). Opportunity: a network of 120 private clinics paid by the provincial health department per verified visit
A26: Grant capital | D26: 3 | E26: 5 | F26: Pilot data on visit volumes and user satisfaction in two districts. | G26: Foundation grant | H26: 1 Foundations
A27: Market-building grants | D27: 5 | E27: 4 | F27: Department agrees a common claims and verification standard. | G27: Foundation / donor market-systems grant | H27: 1 Foundations
A28: Technical assistance | D28: 5 | E28: 4 | F28: Department nominates a contracting lead; scope of the purchasing contract agreed. | G28: DFI project-preparation facility | H28: 2 Preparation
A29: Guarantees | D29: 3 | E29: 1 | F29: Only after a signed purchasing contract and 12 months of on-time claims data. | G29: DFI partial guarantee on department payments | H29: 3 Early deployment
A30: Commercial capital | D30: 2 | E30: 1 | F30: 24 months of verified, on-time payment; receivables book above an agreed size. | G30: Local bank receivables facility | H30: 4 Scale
A31: Reading the example: grants and technical assistance come first because they address the binding constraint (payment credibility) now. The guarantee is planned but held until its entry condition is met. Commercial capital is the end state, not today's ask. Proposed capital stack summary for this case: "Grant + TA now; DFI guarantee after contract signature; bank receivables finance at scale."

Sheet Risk Allocation
A1: Tool 8 | Risk Allocation Worksheet
A3: List each material risk, score Likelihood and Impact (key in row 5) and allocate it to the actor best placed to manage it before choosing an instrument. Inherent score = Likelihood x Impact (maximum 25). Residual risk is a single 1 to 5 rating after mitigation. Do not use guarantees to hide weak design. A worked example sits below the summary.
A5: LIKELIHOOD (next 24 months) 1 = Rare (under 10%) | 2 = Unlikely (10-30%) | 3 = Possible (30-50%) | 4 = Likely (50-80%) | 5 = Almost certain (over 80%). IMPACT 1 = Negligible | 2 = Minor delay or cost | 3 = Material delay or cost; a component must be redesigned | 4 = Major: threatens financing, delivery or a key partner | 5 = Stops the opportunity or causes serious harm to users. RESIDUAL (after mitigation) 1 = Low; accept and monitor | 2 = Minor | 3 = Material; needs active management | 4 = High; escalate | 5 = Could still stop the opportunity.
A6: ID | B6: Risk category | C6: Risk description / event | D6: Likelihood (1–5) | E6: Impact (1–5) | F6: Current owner | G6: Best-placed owner | H6: Treatment | I6: Mitigation / instrument | J6: Residual risk (1–5) | K6: Trigger / monitoring indicator | L6: Inherent score (L x I)
A7: R1 | L7: =IF(COUNT(D7:E7)<2,"",D7*E7)
A8: R2 | L8: =IF(COUNT(D8:E8)<2,"",D8*E8)
A9: R3 | L9: =IF(COUNT(D9:E9)<2,"",D9*E9)
A10: R4 | L10: =IF(COUNT(D10:E10)<2,"",D10*E10)
A11: R5 | L11: =IF(COUNT(D11:E11)<2,"",D11*E11)
A12: R6 | L12: =IF(COUNT(D12:E12)<2,"",D12*E12)
A13: R7 | L13: =IF(COUNT(D13:E13)<2,"",D13*E13)
A14: R8 | L14: =IF(COUNT(D14:E14)<2,"",D14*E14)
A15: R9 | L15: =IF(COUNT(D15:E15)<2,"",D15*E15)
A16: R10 | L16: =IF(COUNT(D16:E16)<2,"",D16*E16)
A17: R11 | L17: =IF(COUNT(D17:E17)<2,"",D17*E17)
A18: R12 | L18: =IF(COUNT(D18:E18)<2,"",D18*E18)
... A26: R20 | L26: =IF(COUNT(D26:E26)<2,"",D26*E26)
A28: Risk summary
A29: Highest inherent risk | B29: =IF(COUNT(L7:L26)=0,"Incomplete",INDEX(C7:C26,MATCH(MAX(L7:L26),L7:L26,0))) -> Incomplete
A30: Average residual risk | B30: =IFERROR(AVERAGE(J7:J26),0) -> 0
A33: Worked example (illustration only, not counted)
A34: R1 | B34: Payment / counterparty | C34: Department pays claims late (over 90 days) during budget transitions. | D34: 4 | E34: 4 | F34: Clinics | G34: Department, backed by a liquidity facility | H34: Mitigate | I34: Liquidity reserve funded by catalytic capital; payment-timing clause in the contract. | J34: 2 | K34: Average claim age above 60 days for two consecutive months. | L34: 16

Sheet Deployability Dashboard
A1: Deployability Dashboard
A3: Executive summary populated from the Excel toolkit. Complete all assessments for a reliable result. The team completes the yellow cells in "Decisions and next steps".
B6: Opportunity
B7: Opportunity | C7: ='Opportunity Profile'!B7 -> 0
B8: Country / geography | C8: ='Opportunity Profile'!B8 -> 0
B9: Sector | C9: ='Opportunity Profile'!B9 -> 0
B10: Lead institution | C10: ='Opportunity Profile'!B10 -> 0
B12: Headline results
B13: Deployability score | C13: ='Deployability Scorecard'!B47 -> 0
B14: Deployability rating | C14: ='Deployability Scorecard'!B48 -> Incomplete
B15: Lowest readiness dimension | C15: ='Deployability Scorecard'!B49 -> Incomplete
B16: Primary binding constraint | C16: =IF('Binding Constraints'!B22<>"",'Binding Constraints'!B22,'Binding Constraints'!B19) -> Incomplete
B17: Recommended model | C17: ='Partnership Model Selection'!B23 -> Incomplete
B18: Best-fit institutional role | C18: ='Role Selection'!B23 -> Incomplete
B19: Highest-priority capital type | C19: ='Capital Sequencing'!B20 -> Incomplete
B20: Highest inherent risk | C20: ='Risk Allocation'!B29 -> Incomplete
B22: Deployability results
B23: Dimension | C23: Average / 5 | D23: RAG
B24: Demand and Market Readiness | C24: ='Deployability Scorecard'!B39 -> 0 | D24: ='Deployability Scorecard'!E39 -> Incomplete
B25: Financial and Capital Readiness | C25: ='Deployability Scorecard'!B40 -> 0 | D25: ='Deployability Scorecard'!E40 -> Incomplete
B26: Delivery and Operational Readiness | C26: ='Deployability Scorecard'!B41 -> 0 | D26: ='Deployability Scorecard'!E41 -> Incomplete
B27: Risk and Structuring Readiness | C27: ='Deployability Scorecard'!B42 -> 0 | D27: ='Deployability Scorecard'!E42 -> Incomplete
B28: Institutional and Coordination Readiness | C28: ='Deployability Scorecard'!B43 -> 0 | D28: ='Deployability Scorecard'!E43 -> Incomplete
B29: Legitimacy and Community Readiness | C29: ='Deployability Scorecard'!B44 -> 0 | D29: ='Deployability Scorecard'!E44 -> Incomplete
B30: System Readiness | C30: ='Deployability Scorecard'!B45 -> 0 | D30: ='Deployability Scorecard'!E45 -> Incomplete
B35: Decisions and next steps
B36: Decision recommendation
B37: Top 3 actions | C37: 1. 2. 3.
B38: Owner and timing
B39: Key assumptions requiring validation
